Workbook

Sheet Tables
B3: Age | C3: Tranche
B4: 0 | C4: Moins de 26 ans
B5: 26 | C5: 26 à < 46 ans
B6: 46 | C6: 46 à < 55 ans
B7: 55 | C7: 55 ans et plus

Sheet Liste salariés
A3: Matricule | B3: Nom Prénom | C3: Date d'entrée | D3: Ancienneté | E3: Date sortie | F3: Naissance | G3: Age | H3: Tranche d'Age | I3: Cat | J3: F/H
A4: 470 | B4: ACEDO Sébastien | C4: 45083 | F4: 34229 | I4: O | J4: H
A5: 330 | B5: AGUERRE Stéphane | C5: 41666 | F5: 25788 | I5: O | J5: H
A6: 387 | B6: AMAT Romain | C6: 43696 | F6: 36376 | I6: E | J6: H
A7: 169 | B7: ARNAL Jean-Marie | C7: 37803 | E7: 45477 | F7: 23865 | I7: E | J7: H
A8: 493 | B8: BAGDASARIANI Eduardi | C8: 45173 | F8: 34425 | I8: O | J8: H
A9: 56 | B9: BEHEREGARAY Jean Michel | C9: 33303 | F9: 23778 | I9: E | J9: H
A10: 50 | B10: BENGOCHEA Emmanuel | C10: 33317 | F10: 25758 | I10: O | J10: H
A11: 145 | B11: BERGEZ Franck | C11: 37221 | F11: 29879 | I11: C | J11: H
A12: 83 | B12: BERROGAIN Jean Baptiste | C12: 32090 | F12: 23902 | I12: E | J12: H
A13: 10000030 | B13: BERTONECHE Tom | C13: 45433 | E13: 45505 | F13: 38314 | I13: O | J13: H
A14: 447 | B14: BIDONDO Anthony | C14: 44613 | F14: 35846 | I14: O | J14: H
A15: 352 | B15: BIDONDO Mickaël | C15: 42598 | F15: 35263 | I15: O | J15: H
A16: 46 | B16: BIDONDO Pierre | C16: 33340 | F16: 24408 | I16: E | J16: H
A17: 10000010 | B17: BONESTEVE Jérôme | C17: 45005 | E17: 45093 | F17: 30997 | I17: O | J17: H
A18: 347 | B18: BRANKAER Alexandre | C18: 42177 | F18: 33637 | I18: O | J18: H
A19: 462 | B19: CAMPANE Jean François | C19: 44837 | F19: 24251 | I19: O | J19: H
A20: 467 | B20: CARRICABURU Alain | C20: 45027 | F20: 31616 | I20: O | J20: H
A21: 403 | B21: CAZENAVE Jean | C21: 44060 | F21: 37368 | I21: O | J21: H
A22: 278 | B22: CHARMAN Maxime | C22: 39713 | F22: 31280 | I22: C | J22: H
A23: 474 | B23: COLAS Martin | C23: 45384 | F23: 37232 | I23: E | J23: H
A24: 341 | B24: CORDANI Jean Marie | C24: 42101 | F24: 27912 | I24: O | J24: H
A25: 353 | B25: CORREIA DOS SANTOS Jorge | C25: 42247 | F25: 25449 | I25: O | J25: H
A26: 181 | B26: COSTA Daniel | C26: 37949 | F26: 29016 | I26: E | J26: H
A27: 318 | B27: COUCHINAVE Eric | C27: 41337 | F27: 28343 | I27: O | J27: H
A28: 129 | B28: COUCHINAVE Sonia | C28: 37712 | F28: 28558 | I28: E | J28: F
A29: 388 | B29: COURTIES Doryan | C29: 43696 | F29: 30030 | I29: E | J29: H
A30: 443 | B30: COURTIES Paul | C30: 44571 | E30: 45555 | F30: 34552 | I30: O | J30: H
A31: 476 | B31: DA COSTA SILVA Sonia | C31: 45159 | E31: 45403 | F31: 28610 | I31: O | J31: F
A32: 471 | B32: DA COSTA-RAMOS Marlène | C32: 45091 | F32: 27141 | I32: O | J32: F
A33: 466 | B33: DA COSTA-RAMOS Sergio | C33: 45019 | F33: 27470 | I33: O | J33: H
A34: 256 | B34: DAGUERRE Patrick | C34: 39328 | F34: 28980 | I34: E | J34: H
A35: 455 | B35: DAVIES Edouard | C35: 44795 | E35: 45631 | F35: 27052 | I35: O | J35: H
A36: 379 | B36: DELGADO Cédric | C36: 43536 | F36: 29936 | I36: O | J36: H
A37: 449 | B37: DEVAUX David | C37: 44620 | F37: 25648 | I37: O | J37: H
A38: 434 | B38: DOS SANTOS Charly | C38: 44424 | F38: 33809 | I38: O | J38: H
A39: 10000033 | B39: DUCHAMP Lionel | C39: 45474 | E39: 45604 | F39: 25789 | I39: O | J39: H
A40: 426 | B40: DUMOLLARD Thierry | C40: 44256 | E40: 45520 | F40: 24965 | I40: O | J40: H
A41: 429 | B41: DUMUR Vincent | C41: 44305 | E41: 45170 | F41: 35352 | I41: O | J41: H
A42: 411 | B42: DUTTER Muriel | C42: 44105 | F42: 27551 | I42: E | J42: F
...

Sheet Liste Formations
A4: N° | B4: Libellé formation | C4: Heures formation
A5: 1001 | B5: Conduite nacelle CACES R486A Plate forme mobile | C5: 21
A6: 1002 | B6: Conduite Chariots Cat.3 et Cat.5 | C6: 14
A7: 1003 | B7: Conduite Chariots Cat.5 | C7: 7 | D7: ETCHE Formation
A8: 1004 | B8: Conduite Chariots Cat.3 | C8: 7
A9: 1005 | B9: Conduite Manuscopique Cat.9 CACES R372M
A10: 1006 | B10: Habilitation électrique BE Manœuvre BS | C10: 14
A11: 1007 | B11: Habilitation électrique BR/BC/B2V/HOV | C11: 10.5
A12: 1008 | B12: Habilitation électrique HC/H2V/HE Manœuvre | C12: 7 | D12: ETCHE Formation
A13: 1034 | B13: Habilitation électrique BR/BC/B2V/HC/H2V/HE Manœuvre | C13: 21
A14: 1009 | B14: Défibrillateur | C14: 2
A15: 1010 | B15: Incendie | C15: 2
A16: 1011 | B16: UTI.COM - SSI / CHUBB
A17: 1012 | B17: ATEX Niveau 0 - Sensibilisation | C17: 3.5
A18: 1013 | B18: ATEX Niveau 1 (1E+1M) Electrique et Mécanique | C18: 14
A19: 1014 | B19: Membres CSE
A20: 1015 | B20: Membres CHSCT
A21: 1016 | B21: S.S.T. Sauveteurs Secourites du Travail | C21: 14
A22: 1017 | B22: R. S.S.T. Recyclage Sauveteurs Secourites du Travail | C22: 7
A23: 1034 | B23: Chauffeur en chaufferie | C23: 7
A24: 1018 | B24: AQI Chaufferies - Agent Qualifié d'Intervention en chaufferies | C24: 7
A25: 1019 | B25: API SIEMENS SIMATIC S7
A26: 1020 | B26: Prévention TMS - Gestes Postures et Nutrition | C26: 3.5
A27: 1021 | B27: Gestion du stress
A28: 1022 | B28: Sensibilisation au bruit | C28: 0.17
A29: 1023 | B29: Chargé de prévention TMS
A30: 1024 | B30: Déversement granulés
A31: 1025 | B31: Manipulation Nanocharges
A32: 1026 | B32: Exposition Produits chimiques
A33: 1027 | B33: Déversement hydrocarbures - Tri déchets
A34: 1028 | B34: PRAP IBC
A35: 1029 | B35: ADR Transport de matières dangereuses
A36: 1030 | B36: Utilisation PTI
A37: 1031 | B37: Référent harcèlement
A38: 1032 | B38: Sensibilisation RPS Risques Psychosociaux
A39: 1033 | B39: Sensibilisation aux addictions
A48: 2001 | B48: IFOCA le mélangeage
... A51: 2004 | B51: Formation Moulage / Sté REP
A52: 2005 | B52: Formation LEAN | C52: 2
A53: 2006 | B53: Exposé TPM Maintenance Productive Totale
...

Sheet Formations effectuées
A1: Formations effectuées
G2: Nombre de formation (filtré) | H2: =SUBTOTAL(2,H7:H1588) -> 1419
G3: Total heures (filtré) | H3: =SUBTOTAL(9,H7:H1696) -> 91370.64
A6: N° matricule | B6: NOM Prénom | C6: Année | D6: Date début | E6: Date fin | F6: Code formation | G6: Libellé formation | H6: Nbre d'heures | I6: Organisme
A7: 470 | B7: ACEDO Sébastien | C7: 2023 | F7: 3040 | G7: =VLOOKUP(F7,'Liste Formations'!$A$5:$B$182,2,FALSE) -> Poste 1404 | H7: 151.67
A8: 470 | B8: ACEDO Sébastien | C8: 2024 | F8: 1020 | G8: =VLOOKUP(F8,'Liste Formations'!$A$5:$B$182,2,FALSE) -> Prévention TMS - Gestes Postures et Nutrition | H8: 3.5
A9: 470 | B9: ACEDO Sébastien | C9: 2024 | F9: 3004 | G9: Poste 510 | H9: 12
A10: 470 | B10: ACEDO Sébastien | C10: 2024 | F10: 3006 | G10: =VLOOKUP(F10,'Liste Formations'!$A$5:$B$182,2,FALSE) -> Poste 515 | H10: 70
A11: 470 | B11: ACEDO Sébastien | C11: 2026 | E11: 46078 | F11: 3040 | G11: Poste 1404 | H11: 105 | I11: Interne
A13: 330 | B13: AGUERRE Stéphane | C13: 2014 | F13: 1004 | G13: =VLOOKUP(F13,'Liste Formations'!$A$5:$B$182,2,FALSE) -> Conduite Chariots Cat.3 | H13: 7
A14: 330 | B14: AGUERRE Stéphane | C14: 2014 | F14: 3025 | G14: =VLOOKUP(F14,'Liste Formations'!$A$5:$B$182,2,FALSE) -> Poste 930 | H14: 151.67
A15: 330 | B15: AGUERRE Stéphane | C15: 2014 | F15: 3041 | G15: =VLOOKUP(F15,'Liste Formations'!$A$5:$B$182,2,FALSE) -> Poste 1405 | H15: 151.67
A16: 330 | B16: AGUERRE Stéphane | C16: 2016 | F16: 3025 | G16: =VLOOKUP(F16,'Liste Formations'!$A$5:$B$182,2,FALSE) -> Poste 930 | H16: 151.67
A17: 330 | B17: AGUERRE Stéphane | C17: 2016 | F17: 3041 | G17: =VLOOKUP(F17,'Liste Formations'!$A$5:$B$182,2,FALSE) -> Poste 1405 | H17: 151.67
A18: 330 | B18: AGUERRE Stéphane | C18: 2017 | F18: 2007 | G18: =VLOOKUP(F18,'Liste Formations'!$A$5:$B$182,2,FALSE) -> ERP DIVALTO | H18: 2
A19: 330 | B19: AGUERRE Stéphane | C19: 2018 | F19: 1020 | G19: =VLOOKUP(F19,'Liste Formations'!$A$5:$B$182,2,FALSE) -> Prévention TMS - Gestes Postures et Nutrition | H19: 3.5
A20: 330 | B20: AGUERRE Stéphane | C20: 2018 | F20: 3010 | G20: =VLOOKUP(F20,'Liste Formations'!$A$5:$B$182,2,FALSE) -> Poste 830 | H20: 151.67
A21: 330 | B21: AGUERRE Stéphane | C21: 2018 | F21: 3025 | G21: =VLOOKUP(F21,'Liste Formations'!$A$5:$B$182,2,FALSE) -> Poste 930 | H21: 151.67
A22: 330 | B22: AGUERRE Stéphane | C22: 2018 | F22: 3041 | G22: =VLOOKUP(F22,'Liste Formations'!$A$5:$B$182,2,FALSE) -> Poste 1405 | H22: 151.67
A23: 330 | B23: AGUERRE Stéphane | C23: 2019 | F23: 1004 | G23: =VLOOKUP(F23,'Liste Formations'!$A$5:$B$182,2,FALSE) -> Conduite Chariots Cat.3 | H23: 7
A24: 330 | B24: AGUERRE Stéphane | C24: 2021 | F24: 3014 | G24: =VLOOKUP(F24,'Liste Formations'!$A$5:$B$182,2,FALSE) -> Poste 902 | H24: 151.67
... A29: 330 | B29: AGUERRE Stéphane | C29: 2024 | F29: 1020 | G29: =VLOOKUP(F29,'Liste Formations'!$A$5:$B$182,2,FALSE) -> Prévention TMS - Gestes Postures et Nutrition | H29: 3.5
A30: 330 | B30: AGUERRE Stéphane | C30: 2025 | D30: 45723 | E30: 45754 | F30: 3037 | G30: Poste 1121 | H30: 35 | I30: Interne
A32: 387 | B32: AMAT Romain | C32: 2019 | F32: 1001 | G32: =VLOOKUP(F32,'Liste Formations'!$A$5:$B$182,2,FALSE) -> Conduite nacelle CACES R486A Plate forme mobile | H32: 14
A33: 387 | B33: AMAT Romain | C33: 2019 | F33: 1004 | G33: =VLOOKUP(F33,'Liste Formations'!$A$5:$B$182,2,FALSE) -> Conduite Chariots Cat.3 | H33: 7
A34: 387 | B34: AMAT Romain | C34: 2021 | F34: 1018 | G34: =VLOOKUP(F34,'Liste Formations'!$A$5:$B$182,2,FALSE) -> AQI Chaufferies - Agent Qualifié d'Intervention en chaufferies | H34: 21
A35: 387 | B35: AMAT Romain | C35: 2022 | F35: 1007 | G35: =VLOOKUP(F35,'Liste Formations'!$A$5:$B$182,2,FALSE) -> Habilitation électrique BR/BC/B2V/HOV | H35: 21
A36: 387 | B36: AMAT Romain | C36: 2024 | F36: 1001 | G36: =VLOOKUP(F36,'Liste Formations'!$A$5:$B$182,2,FALSE) -> Conduite nacelle CACES R486A Plate forme mobile | H36: 21
A37: 387 | B37: AMAT Romain | C37: 2024 | F37: 1004 | G37: =VLOOKUP(F37,'Liste Formations'!$A$5:$B$182,2,FALSE) -> Conduite Chariots Cat.3 | H37: 7
A38: 387 | B38: AMAT Romain | C38: 2024 | F38: 1013 | G38: =VLOOKUP(F38,'Liste Formations'!$A$5:$B$182,2,FALSE) -> ATEX Niveau 1 (1E+1M) Electrique et Mécanique | H38: 14
A39: 387 | B39: AMAT Romain | C39: 2024 | F39: 1018 | G39: =VLOOKUP(F39,'Liste Formations'!$A$5:$B$182,2,FALSE) -> AQI Chaufferies - Agent Qualifié d'Intervention en chaufferies | H39: 7
A40: 387 | B40: AMAT Romain | C40: 2025 | D40: 45747 | E40: 45748 | F40: 1007 | G40: Habilitation électrique BR/BC/B2V/HOV | H40: 10.5 | I40: ETCHE Formation
A41: 387 | B41: AMAT Romain | C41: 2025 | D41: 45776 | E41: 45776 | F41: 1008 | G41: Habilitation électrique HC/H2V/HE Manœuvre | H41: 7 | I41: ETCHE Formation
A45: 414 | B45: ARNAL Damien | C45: 2020 | F45: 3038 | G45: =VLOOKUP(F45,'Liste Formations'!$A$5:$B$182,2,FALSE) -> Poste 1401 | H45: 120
A46: 414 | B46: ARNAL Damien | C46: 2021 | F46: 1004 | G46: =VLOOKUP(F46,'Liste Formations'!$A$5:$B$182,2,FALSE) -> Conduite Chariots Cat.3 | H46: 7
A47: 414 | B47: ARNAL Damien | C47: 2021 | F47: 3013 | G47: =VLOOKUP(F47,'Liste Formations'!$A$5:$B$182,2,FALSE) -> Poste 901 | H47: 396.67
A48: 414 | B48: ARNAL Damien | C48: 2021 | F48: 3018 | G48: =VLOOKUP(F48,'Liste Formations'!$A$5:$B$182,2,FALSE) -> Poste 906 | H48: 151.67
A49: 414 | B49: ARNAL Damien | C49: 2021 | F49: 3023 | G49: =VLOOKUP(F49,'Liste Formations'!$A$5:$B$182,2,FALSE) -> Poste 923 | H49: 151.67
A50: 414 | B50: ARNAL Damien | C50: 2021 | F50: 3038 | G50: =VLOOKUP(F50,'Liste Formations'!$A$5:$B$182,2,FALSE) -> Poste 1401 | H50: 151.67
A51: 414 | B51: ARNAL Damien | C51: 2022 | F51: 3001 | G51: =VLOOKUP(F51,'Liste Formations'!$A$5:$B$182,2,FALSE) -> Poste 506 | H51: 151.67
...

Sheet Formulaire individuel
A1: Date : | B1: =TODAY() -> 46092
A3: N° Matricule : | C3: 258
A5: Nom Prénom : | C5: =VLOOKUP(C3,'Liste salariés'!A3:G104,2,FALSE) -> JOUMAH HASSAN
A6: Date naissance : | C6: =VLOOKUP(C3,'Liste salariés'!A3:J103,6,FALSE) -> 22426 | D6: Age : | E6: =(B1-C6)/365 -> 64.838356
A7: Date d'entrée : | C7: =VLOOKUP(C3,'Liste salariés'!A3:J105,3,FALSE) -> 39364 | D7: Ancienneté : | E7: =(B1-C7)/365 -> 18.432877
A10: Liste des formations effectuées :
A12: Code formation | B12: Intitulé | E12: Organisme | F12: Date début | G12: Date fin | H12: Durée (h)
A13: 2046 | B13: =VLOOKUP(A13,'Liste Formations'!$A$5:$B$154,2,FALSE) -> IFOCA - Formulation des caoutchoucs : INITIATION | G13: 2009 | H13: 35
A14: 2003 | B14: =VLOOKUP(A14,'Liste Formations'!$A$5:$B$154,2,FALSE) -> CIRAD / Les secrets d'un polymère | G14: 2011 | H14: 14
A15: 2005 | B15: =VLOOKUP(A15,'Liste Formations'!$A$5:$B$154,2,FALSE) -> Formation LEAN | G15: 2011 | H15: 7
A16: 2014 | B16: =VLOOKUP(A16,'Liste Formations'!$A$5:$B$154,2,FALSE) -> Gestion Projet + ISO T.S. | G16: 2013 | H16: 7
A17: 1011 | B17: =VLOOKUP(A17,'Liste Formations'!$A$5:$B$154,2,FALSE) -> UTI.COM - SSI / CHUBB | G17: 2014 | H17: 4
A18: 2007 | B18: =VLOOKUP(A18,'Liste Formations'!$A$5:$B$154,2,FALSE) -> ERP DIVALTO | G18: 2016 | H18: 7
A19: 2029 | B19: =VLOOKUP(A19,'Liste Formations'!$A$5:$B$154,2,FALSE) -> CORE TOOLS | G19: 2016 | H19: 7
A20: 2007 | B20: =VLOOKUP(A20,'Liste Formations'!$A$5:$B$154,2,FALSE) -> ERP DIVALTO | G20: 2017 | H20: 21
A21: 1021 | B21: =VLOOKUP(A21,'Liste Formations'!$A$5:$B$154,2,FALSE) -> Gestion du stress | G21: 2018 | H21: 4
A22: 2007 | B22: =VLOOKUP(A22,'Liste Formations'!$A$5:$B$154,2,FALSE) -> ERP DIVALTO | G22: 2019 | H22: 14
A23: 2021 | B23: =VLOOKUP(A23,'Liste Formations'!$A$5:$B$154,2,FALSE) -> ENTERPRISE / ALPHA TECHNOLOGIE | G23: 2019 | H23: 7
A24: 1009 | B24: =VLOOKUP(A24,'Liste Formations'!$A$5:$B$154,2,FALSE) -> Défibrillateur | G24: 2019 | H24: 3
... A27: 2040 | B27: =VLOOKUP(A27,'Liste Formations'!$A$5:$B$154,2,FALSE) -> Anglais | G27: 2024 | H27: 13.5

Sheet TARDY
A1: Date : | B1: 44985
A3: N° Matricule : | C3: 102
A5: Nom Prénom : | C5: TARDY Jean-Marie
A6: Date naissance : | C6: 23238 | D6: Age : | E6: =(B1-C6)/365 -> 59.580822
A7: Date d'entrée : | C7: 36619 | D7: Ancienneté : | E7: =(B1-C7)/365 -> 22.920548
A10: Liste des formations effectuées :
A12: Code formation | B12: Intitulé | E12: Organisme | F12: Date début | G12: Date fin | H12: Durée (h)
A13: 3043 | B13: Poste 1412 | G13: 2003 | H13: 151.67
A14: 3012 | B14: Poste 900 | G14: 2004 | H14: 151.67
A15: 3012 | B15: Poste 900 | G15: 2005 | H15: 151.67
A16: 3012 | B16: Poste 900 | G16: 2007 | H16: 151.67
A17: 3012 | B17: Poste 900 | G17: 2009 | H17: 151.67
A18: 3020 | B18: Poste 908 | G18: 2009 | H18: 151.67
A19: 3043 | B19: Poste 1412 | G19: 2009 | H19: 151.67
A20: 1004 | B20: Conduite Chariots Cat.3 | G20: 2011 | H20: 7
A21: 2047 | B21: IFOCA - Le mélangeage | G21: 2011 | H21: 42
A22: 3012 | B22: Poste 900 | G22: 2011 | H22: 151.67
A23: 3020 | B23: Poste 908 | G23: 2011 | H23: 151.67
A24: 3043 | B24: Poste 1412 | G24: 2011 | H24: 151.67
... A36: 3012 | B36: Poste 900 | G36: 2019 | H36: 151.67

Sheet CORREIA DOS SANTOS Jorge
A1: Date : | B1: =TODAY() -> 46092
A3: N° Matricule : | C3: 353
A5: Nom Prénom : | C5: CORREIA DOS SANTOS Jorge
A6: Date naissance : | C6: 25449 | D6: Age : | E6: =(B1-C6)/365 -> 56.556164
A7: Date d'entrée : | C7: 42247 | D7: Ancienneté : | E7: =(B1-C7)/365 -> 10.534247
A10: Liste des formations effectuées :
A12: Code formation | B12: Intitulé | E12: Organisme | F12: Date début | G12: Date fin | H12: Durée (h)
A14: 1004 | B14: Conduite Chariots Cat.3 | E14: ETCHE Formation | G14: 2015 | H14: 7 | L14: 353 | M14: CORREIA DOS SANTOS Jorge | N14: 2015 | Q14: 1004 | R14: =VLOOKUP(Q14,'Liste Formations'!$A$5:$B$182,2,FALSE) -> Conduite Chariots Cat.3 | S14: 7 | T14: ETCHE Formation
A15: 3043 | B15: Poste 1412 | E15: Interne | G15: 2015 | H15: 151.67 | L15: 353 | M15: CORREIA DOS SANTOS Jorge | N15: 2015 | Q15: 3043 | R15: =VLOOKUP(Q15,'Liste Formations'!$A$5:$B$182,2,FALSE) -> Poste 1412 | S15: 151.67 | T15: Interne
A16: 3043 | B16: Poste 1412 | E16: Interne | G16: 2017 | H16: 151.67 | L16: 353 | M16: CORREIA DOS SANTOS Jorge | N16: 2017 | Q16: 3043 | R16: =VLOOKUP(Q16,'Liste Formations'!$A$5:$B$182,2,FALSE) -> Poste 1412 | S16: 151.67 | T16: Interne
A17: 2007 | B17: ERP DIVALTO | E17: Interne | G17: 2017 | H17: 2.5 | L17: 353 | M17: CORREIA DOS SANTOS Jorge | N17: 2017 | Q17: 2007 | R17: =VLOOKUP(Q17,'Liste Formations'!$A$5:$B$182,2,FALSE) -> ERP DIVALTO | S17: 2.5 | T17: Interne
A18: 1020 | B18: Prévention TMS - Gestes Postures et Nutrition | E18: Kine Santé Prévention | G18: 2018 | H18: 3.5 | L18: 353 | M18: CORREIA DOS SANTOS Jorge | N18: 2018 | Q18: 1020 | R18: =VLOOKUP(Q18,'Liste Formations'!$A$5:$B$182,2,FALSE) -> Prévention TMS - Gestes Postures et Nutrition | S18: 3.5 | T18: Kine Santé Prévention
A19: 3043 | B19: Poste 1412 | E19: Interne | G19: 2019 | H19: 151.67 | L19: 353 | M19: CORREIA DOS SANTOS Jorge | N19: 2019 | Q19: 3043 | R19: =VLOOKUP(Q19,'Liste Formations'!$A$5:$B$182,2,FALSE) -> Poste 1412 | S19: 151.67 | T19: Interne
A20: 3043 | B20: Poste 1412 | E20: Interne | G20: 2021 | H20: 151.67 | L20: 353 | M20: CORREIA DOS SANTOS Jorge | N20: 2021 | Q20: 3043 | R20: =VLOOKUP(Q20,'Liste Formations'!$A$5:$B$182,2,FALSE) -> Poste 1412 | S20: 151.67 | T20: Interne
A21: 1012 | B21: ATEX Niveau 0 - Sensibilisation | E21: APAVE | G21: 2023 | H21: 3.5 | L21: 353 | M21: CORREIA DOS SANTOS Jorge | N21: 2023 | Q21: 1012 | R21: =VLOOKUP(Q21,'Liste Formations'!$A$5:$B$182,2,FALSE) -> ATEX Niveau 0 - Sensibilisation | S21: 3.5 | T21: APAVE
A22: 1009 | B22: Défibrillateur | E22: Interne | G22: 2023 | H22: 2 | L22: 353 | M22: CORREIA DOS SANTOS Jorge | N22: 2023 | Q22: 1009 | R22: =VLOOKUP(Q22,'Liste Formations'!$A$5:$B$182,2,FALSE) -> Défibrillateur | S22: 2 | T22: Interne
A23: 1010 | B23: Incendie | E23: Interne | G23: 2023 | H23: 2 | L23: 353 | M23: CORREIA DOS SANTOS Jorge | N23: 2023 | Q23: 1010 | R23: Incendie | S23: 2 | T23: Interne
A24: 1004 | B24: Conduite Chariots Cat.3 | E24: ETCHE Formation | G24: 2023 | H24: 7 | L24: 353 | M24: CORREIA DOS SANTOS Jorge | N24: 2023 | Q24: 1004 | R24: =VLOOKUP(Q24,'Liste Formations'!$A$5:$B$182,2,FALSE) -> Conduite Chariots Cat.3 | S24: 7 | T24: ETCHE Formation
A25: 1003 | B25: Conduite Chariots Cat.5 | E25: ETCHE Formation | G25: 2023 | H25: 4 | L25: 353 | M25: CORREIA DOS SANTOS Jorge | N25: 2023 | Q25: 1003 | R25: =VLOOKUP(Q25,'Liste Formations'!$A$5:$B$182,2,FALSE) -> Conduite Chariots Cat.5 | S25: 4 | T25: ETCHE Formation
A26: 1010 | B26: Incendie | E26: Interne | G26: 2024 | H26: 2 | L26: 353 | M26: CORREIA DOS SANTOS Jorge | N26: 2024 | Q26: 1010 | R26: Incendie | S26: 2 | T26: Interne
A27: 1009 | B27: Défibrillateur | E27: Interne | G27: 2024 | H27: 2 | L27: 353 | M27: CORREIA DOS SANTOS Jorge | N27: 2024 | Q27: 1009 | R27: =VLOOKUP(Q27,'Liste Formations'!$A$5:$B$182,2,FALSE) -> Défibrillateur | S27: 2 | T27: Interne

Sheet LORDON
A1: Date : | B1: 44957
A3: N° Matricule : | C3: 52
A5: Nom Prénom : | C5: LORDON Jean-Baptiste
A6: Date naissance : | C6: 23003 | D6: Age : | E6: =(B1-C6)/365 -> 60.147945
A7: Date d'entrée : | C7: 32090 | D7: Ancienneté : | E7: =(B1-C7)/365 -> 35.252055
A10: Liste des formations effectuées :
A12: Code formation | B12: Intitulé | E12: Organisme | F12: Date début | G12: Date fin | H12: Durée (h)
A13: 3001 | B13: Poste 506 | G13: 2003 | H13: 151.67
A14: 3001 | B14: Poste 506 | G14: 2004 | H14: 151.67
A15: 3005 | B15: Poste 514 | G15: 2004 | H15: 151.67
A16: 3005 | B16: Poste 514 | G16: 2005 | H16: 151.67
A17: 3001 | B17: Poste 506 | G17: 2005 | H17: 151.67
A18: 3001 | B18: Poste 506 | G18: 2007 | H18: 151.67
A19: 3005 | B19: Poste 514 | G19: 2007 | H19: 151.67
A20: 3001 | B20: Poste 506 | G20: 2009 | H20: 151.67
A21: 3005 | B21: Poste 514 | G21: 2009 | H21: 151.67
A22: 3038 | B22: Poste 1401 | G22: 2009 | H22: 151.67
A23: 3005 | B23: Poste 514 | G23: 2010 | H23: 151.67
A24: 2047 | B24: IFOCA - Le mélangeage | G24: 2011 | H24: 42
... A60: 3015 | B60: Poste 903 | G60: 2021 | H60: 151.67

Sheet LEPOLARD B
A1: Date : | B1: 44722
A3: N° Matricule : | C3: 421
A5: Nom Prénom : | C5: LEPOLARD Baptiste
A6: Date naissance : | C6: 33162 | D6: Age : | E6: =(B1-C6)/365 -> 31.671233
A7: Date d'entrée : | C7: 44207 | D7: Ancienneté : | E7: =(B1-C7)/365 -> 1.4109589
A10: Liste des formations effectuées :
A12: Code formation | B12: Intitulé | E12: Organisme | F12: Date début | G12: Date fin | H12: Durée (h)
A13: 3014 | B13: Poste 902 | G13: 2021 | H13: 151.67
A14: 1004 | B14: Conduite Chariots Cat.3 | G14: 2021 | H14: 7
A15: 3024 | B15: Poste 924 | G15: 2021 | H15: 105
A16: 3018 | B16: Poste 906 | G16: 2021 | H16: 151.67
A17: 3039 | B17: Poste 1402 | G17: 2021 | H17: 79
A18: 3015 | B18: Poste 903 | G18: 2021 | H18: 151.67
A19: 3024 | B19: Poste 924 | G19: 2021 | H19: 151.67
A20: 3026 | B20: Poste 940 | G20: 2021 | H20: 151.67
A21: 3039 | B21: Poste 1402 | G21: 2021 | H21: 151.67

Sheet MENDRIBIL
A1: Date : | B1: 44227
A3: N° Matricule : | C3: 36
A5: Nom Prénom : | C5: MENDRIBIL Alain
A6: Date naissance : | C6: 22418 | D6: Age : | E6: =(B1-C6)/365 -> 59.750685
A7: Date d'entrée : | C7: 34620 | D7: Ancienneté : | E7: =(B1-C7)/365 -> 26.320548
A10: Liste des formations effectuées :
A12: Code formation | B12: Intitulé | E12: Organisme | F12: Date début | G12: Date fin | H12: Durée (h)
A13: 3012 | B13: Poste 900 | G13: 1996 | H13: 151.67
A14: 3019 | B14: Poste 910 | G14: 1997 | H14: 151.67
A15: 3036 | B15: Poste 1109 | G15: 1998 | H15: 151.67
A16: 3039 | B16: Poste 1402 | G16: 2003 | H16: 151.67
A17: 3039 | B17: Poste 1402 | G17: 2004 | H17: 151.67
A18: 3039 | B18: Poste 1402 | G18: 2005 | H18: 151.67
A19: 3039 | B19: Poste 1402 | G19: 2007 | H19: 151.67
A20: 3039 | B20: Poste 1402 | G20: 2009 | H20: 151.67
A21: 2047 | B21: IFOCA - Le mélangeage | G21: 2011 | H21: 42
A22: 3039 | B22: Poste 1402 | G22: 2011 | H22: 151.67
A23: 3039 | B23: Poste 1402 | G23: 2013 | H23: 151.67
A24: 3002 | B24: Poste 507 | G24: 2013 | H24: 151.67
... A36: 3026 | B36: Poste 940 | G36: 2020 | H36: 16

Sheet SIMON Th
A1: Date : | B1: 44589
A3: N° Matricule : | C3: 327
A5: Nom Prénom : | C5: SIMON Thomas
A6: Date naissance : | C6: 33833 | D6: Age : | E6: =(B1-C6)/365 -> 29.468493
A7: Date d'entrée : | C7: 41505 | D7: Ancienneté : | E7: =(B1-C7)/365 -> 8.4493151
A10: Liste des formations effectuées :
A12: Code formation | B12: Intitulé | E12: Organisme | F12: Date début | G12: Date fin | H12: Durée (h)
A13: 3038 | B13: Poste 1401 | G13: 2013 | H13: 151.67
A14: 1004 | B14: Conduite Chariots Cat.3 | G14: 2014 | H14: 7
A15: 1020 | B15: Prévention TMS - Gestes Postures et Nutrition | G15: 2014 | H15: 3.5
A16: 3038 | B16: Poste 1401 | G16: 2015 | H16: 151.67
A17: 2007 | B17: ERP DIVALTO | G17: 2017 | H17: 2
A18: 3038 | B18: Poste 1401 | G18: 2017 | H18: 151.67
A19: 3007 | B19: Poste 516 | G19: 2017 | H19: 151.67
A20: 1010 | B20: Incendie | G20: 2018 | H20: 2
A21: 1009 | B21: Défibrillateur | G21: 2018 | H21: 2
A22: 3006 | B22: Poste 515 | G22: 2018 | H22: 151.67
A23: 3038 | B23: Poste 1401 | G23: 2019 | H23: 151.67
A24: 1016 | B24: S.S.T. Sauveteurs Secourites du Travail | G24: 2019 | H24: 14
... A49: 3023 | B49: Poste 923 | G49: 2021 | H49: 151.67

Sheet MARQUES
A1: Date : | B1: 44806
A3: N° Matricule : | C3: 381
A5: Nom Prénom : | C5: MARQUES Pauline
A6: Date naissance : | C6: 34914 | D6: Age : | E6: =(B1-C6)/365 -> 27.10137
A7: Date d'entrée : | C7: 43620 | D7: Ancienneté : | E7: =(B1-C7)/365 -> 3.2493151
A10: Liste des formations effectuées :
A12: Code formation | B12: Intitulé | E12: Organisme | F12: Date début | G12: Date fin | H12: Durée (h)
A13: 3041 | B13: Poste 1405 | G13: 2019 | H13: 151.67
A14: 3042 | B14: Poste 1406 | G14: 2019 | H14: 151.67
A15: 1004 | B15: Conduite Chariots Cat.3 | G15: 2019 | H15: 7
A16: 1010 | B16: Incendie | G16: 2019 | H16: 2
A17: 1009 | B17: Défibrillateur | G17: 2019 | H17: 2

Sheet PICOT
A1: Date : | B1: =TODAY() -> 46092
A3: N° Matricule : | C3: 400
A5: Nom Prénom : | C5: =VLOOKUP(C3,'Liste salariés'!A3:G104,2,FALSE) -> PICOT Frédéric
A6: Date naissance : | C6: =VLOOKUP(C3,'Liste salariés'!A3:J103,6,FALSE) -> 28137 | D6: Age : | E6: =(B1-C6)/365 -> 49.191781
A7: Date d'entrée : | C7: =VLOOKUP(C3,'Liste salariés'!A3:J105,3,FALSE) -> 43871 | D7: Ancienneté : | E7: =(B1-C7)/365 -> 6.0849315
A10: Liste des formations effectuées :
A12: Code formation | B12: Intitulé | E12: Organisme | F12: Date début | G12: Date fin | H12: Durée (h)
A13: 3041 | B13: Poste 1405 | G13: 2020 | H13: 360
A14: 1002 | B14: Conduite Chariots Cat.3 et Cat.5 | G14: 2023 | H14: 14
A15: 1009 | B15: Défibrillateur | G15: 2023 | H15: 2
A16: 1010 | B16: Incendie | G16: 2023 | H16: 2
A17: 1014 | B17: Membres CSE | G17: 2023 | H17: 35
A18: 1016 | B18: S.S.T. Sauveteurs Secourites du Travail | G18: 2023 | H18: 14
A19: 3012 | B19: Poste 900 | G19: 2023 | H19: 151.67
A20: 3045 | B20: Poste de travail | G20: 2023 | H20: 151.67

Sheet BERCAITS
A1: Date : | B1: 44918
A3: N° Matricule : | C3: 301
A5: Nom Prénom : | C5: BERCAITS François
A6: Date naissance : | C6: 21633 | D6: Age : | E6: =(B1-C6)/365 -> 63.794521
A7: Date d'entrée : | C7: 40575 | D7: Ancienneté : | E7: =(B1-C7)/365 -> 11.89863
A10: Liste des formations effectuées :
A12: Code formation | B12: Intitulé | E12: Organisme | F12: Date début | G12: Date fin | H12: Durée (h)
A13: 3038 | B13: Poste 1401 | G13: 2011 | H13: 151.67
A14: 2047 | B14: IFOCA - Le mélangeage | G14: 2011 | H14: 42
A15: 1020 | B15: Prévention TMS - Gestes Postures et Nutrition | G15: 2012 | H15: 3.5
A16: 3038 | B16: Poste 1401 | G16: 2013 | H16: 151.67
A17: 2005 | B17: Formation LEAN | G17: 2015 | H17: 2
A18: 1010 | B18: Incendie | G18: 2015 | H18: 2
A19: 3038 | B19: Poste 1401 | G19: 2015 | H19: 151.67
A20: 2007 | B20: ERP DIVALTO | G20: 2017 | H20: 2.5
A21: 3038 | B21: Poste 1401 | G21: 2017 | H21: 151.67
A22: 3001 | B22: Poste 506 | G22: 2018 | H22: 151.67
A23: 1020 | B23: Prévention TMS - Gestes Postures et Nutrition | G23: 2018 | H23: 3.5
A24: 3001 | B24: Poste 506 | G24: 2019 | H24: 151.67
A25: 3038 | B25: Poste 1401 | G25: 2019 | H25: 151.67

Sheet DAVIES
A1: Date : | B1: =TODAY() -> 46092
A3: N° Matricule : | C3: 455
A5: Nom Prénom : | C5: =VLOOKUP(C3,'Liste salariés'!A3:G104,2,FALSE) -> DAVIES Edouard
A6: Date naissance : | C6: =VLOOKUP(C3,'Liste salariés'!A3:J103,6,FALSE) -> 27052 | D6: Age : | E6: =(B1-C6)/365 -> 52.164384
A7: Date d'entrée : | C7: =VLOOKUP(C3,'Liste salariés'!A3:J105,3,FALSE) -> 44795 | D7: Ancienneté : | E7: =(B1-C7)/365 -> 3.5534247
A10: Liste des formations effectuées :
A12: Code formation | B12: Intitulé | E12: Organisme | F12: Date début | G12: Date fin | H12: Durée (h)
A13: 3010 | B13: Poste 830 | G13: 2022 | H13: 151.67
A14: 1004 | B14: Conduite Chariots Cat.3 | G14: 2023 | H14: 10.5
A15: 3038 | B15: Poste 1401 | G15: 2023 | H15: 151.67
A16: 1008 | B16: Habilitation électrique HC/H2V/HE Manœuvre | G16: 2024 | H16: 2
A17: 1009 | B17: Défibrillateur | G17: 2024 | H17: 2
A18: 1016 | B18: S.S.T. Sauveteurs Secourites du Travail | G18: 2024 | H18: 14
A19: 3001 | B19: Poste 506 | G19: 2024 | H19: 151.67

Sheet PEREZ
A1: Date : | B1: =TODAY() -> 46092
A3: N° Matricule : | C3: 157
A5: Nom Prénom : | C5: =VLOOKUP(C3,'Liste salariés'!A3:G104,2,FALSE) -> PEREZ Xavier
A6: Date naissance : | C6: =VLOOKUP(C3,'Liste salariés'!A3:J103,6,FALSE) -> 25068 | D6: Age : | E6: =(B1-C6)/365 -> 57.6
A7: Date d'entrée : | C7: =VLOOKUP(C3,'Liste salariés'!A3:J105,3,FALSE) -> 37803 | D7: Ancienneté : | E7: =(B1-C7)/365 -> 22.709589
A10: Liste des formations effectuées :
A12: Code formation | B12: Intitulé | E12: Organisme | F12: Date début | G12: Date fin | H12: Durée (h)
A13: 2001 | B13: IFOCA le mélangeage | G13: 2011 | H13: 42
A14: 3002 | B14: Poste 507 | G14: 2011 | H14: 151.67
A15: 3003 | B15: Poste 509 | G15: 2011 | H15: 151.67
A16: 3004 | B16: Poste 510 | G16: 2011 | H16: 151.67
A17: 3006 | B17: Poste 515 | G17: 2011 | H17: 151.67
A18: 3039 | B18: Poste 1402 | G18: 2011 | H18: 151.67
A19: 3040 | B19: Poste 1404 | G19: 2011 | H19: 151.67
A20: 3002 | B20: Poste 507 | G20: 2013 | H20: 151.67
A21: 3003 | B21: Poste 509 | G21: 2013 | H21: 151.67
A22: 3006 | B22: Poste 515 | G22: 2013 | H22: 151.67
A23: 3039 | B23: Poste 1402 | G23: 2013 | H23: 151.67
A24: 3040 | B24: Poste 1404 | G24: 2013 | H24: 151.67
... A45: 3037 | B45: Poste 1121 | G45: 2024 | H45: 151.67

Sheet BIDONDO M
A1: Date : | B1: =TODAY() -> 46092
A3: N° Matricule : | C3: 352
A5: Nom Prénom : | C5: =VLOOKUP(C3,'Liste salariés'!A3:G104,2,FALSE) -> BIDONDO Mickaël
A6: Date naissance : | C6: =VLOOKUP(C3,'Liste salariés'!A3:J103,6,FALSE) -> 35263 | D6: Age : | E6: =(B1-C6)/365 -> 29.668493
A7: Date d'entrée : | C7: =VLOOKUP(C3,'Liste salariés'!A3:J105,3,FALSE) -> 42598 | D7: Ancienneté : | E7: =(B1-C7)/365 -> 9.5726027
A10: Liste des formations effectuées :
A12: Code formation | B12: Intitulé | E12: Organisme | F12: Date début | G12: Date fin | H12: Durée (h)
A13: 3033 | B13: Poste 1101 | G13: 2015 | H13: 151.67
A14: 3037 | B14: Poste 1121 | G14: 2016 | H14: 151.67
A15: 3002 | B15: Poste 507 | G15: 2017 | H15: 151.67
A16: 3005 | B16: Poste 514 | G16: 2017 | H16: 151.67
A17: 3006 | B17: Poste 515 | G17: 2017 | H17: 151.67
A18: 3007 | B18: Poste 516 | G18: 2017 | H18: 151.67
A19: 3008 | B19: Poste 560 | G19: 2017 | H19: 151.67
A20: 3033 | B20: Poste 1101 | G20: 2017 | H20: 151.67
A21: 2007 | B21: ERP DIVALTO | G21: 2017 | H21: 2.5
A22: 3032 | B22: Poste 1100 | G22: 2018 | H22: 151.67
A23: 3034 | B23: Poste 1103 | G23: 2018 | H23: 151.67
A24: 3037 | B24: Poste 1121 | G24: 2018 | H24: 151.67
... A59: 2031 | B59: Qualité | G59: 2025 | H59: 2.5

Sheet MILAGE
A1: Date : | B1: =TODAY() -> 46092
A3: N° Matricule : | C3: 428
A5: Nom Prénom : | C5: =VLOOKUP(C3,'Liste salariés'!A3:G104,2,FALSE) -> MILAGE Alban
A6: Date naissance : | C6: =VLOOKUP(C3,'Liste salariés'!A3:J103,6,FALSE) -> 37494 | D6: Age : | E6: =(B1-C6)/365 -> 23.556164
A7: Date d'entrée : | C7: =VLOOKUP(C3,'Liste salariés'!A3:J105,3,FALSE) -> 44264 | D7: Ancienneté : | E7: =(B1-C7)/365 -> 5.0082192
A10: Liste des formations effectuées :
A12: Code formation | B12: Intitulé | E12: Organisme | F12: Date début | G12: Date fin | H12: Durée (h)
A13: 1004 | B13: Conduite Chariots Cat.3 | G13: 2021 | H13: 7
A14: 3010 | B14: Poste 830 | G14: 2021 | H14: 151.67
A15: 3006 | B15: Poste 515 | G15: 2022 | H15: 151.67
A16: 3025 | B16: Poste 930 | G16: 2022 | H16: 151.67
A17: 3007 | B17: Poste 516 | G17: 2023 | H17: 151.67
A18: 1030 | B18: Utilisation PTI | G18: 2023 | H18: 0.5
A19: 1009 | B19: Défibrillateur | G19: 2024 | H19: 2
A20: 1010 | B20: Incendie | G20: 2024 | H20: 2
A21: 3011 | B21: Poste 834 | G21: 2024 | H21: 16
A22: 3037 | B22: Poste 1121 | G22: 2024 | H22: 151.67
A23: 3032 | B23: Poste 1100 | G23: 2025 | H23: 35

Sheet CAZENAVE
A1: Date : | B1: =TODAY() -> 46092
A3: N° Matricule : | C3: 403
A5: Nom Prénom : | C5: =VLOOKUP(C3,'Liste salariés'!A3:G104,2,FALSE) -> CAZENAVE Jean
A6: Date naissance : | C6: =VLOOKUP(C3,'Liste salariés'!A3:J103,6,FALSE) -> 37368 | D6: Age : | E6: =(B1-C6)/365 -> 23.90137
A7: Date d'entrée : | C7: =VLOOKUP(C3,'Liste salariés'!A3:J105,3,FALSE) -> 44060 | D7: Ancienneté : | E7: =(B1-C7)/365 -> 5.5671233
A10: Liste des formations effectuées :
A12: Code formation | B12: Intitulé | E12: Organisme | F12: Date début | G12: Date fin | H12: Durée (h)
A13: 3041 | B13: Poste 1405 | G13: 2020 | H13: 360
A14: 3016 | B14: Poste 904 | G14: 2020 | H14: 26
A15: 3007 | B15: Poste 516 | G15: 2020 | H15: 151.67
A16: 1004 | B16: Conduite Chariots Cat.3 | G16: 2020 | H16: 7
A17: 3002 | B17: Poste 507 | G17: 2021 | H17: 151.67
A18: 3016 | B18: Poste 904 | G18: 2021 | H18: 151.67
A19: 3001 | B19: Poste 506 | G19: 2023 | H19: 151.67
A20: 3004 | B20: Poste 510 | G20: 2023 | H20: 151.67
A21: 3008 | B21: Poste 560 | G21: 2024 | H21: 151.67
A22: 3037 | B22: Poste 1121 | G22: 2024 | H22: 151.67
A23: 2031 | B23: Qualité | G23: 2024 | H23: 2
A24: 1020 | B24: Prévention TMS - Gestes Postures et Nutrition | G24: 2024 | H24: 3.5
... A27: 3048 | B27: Poste 561 | G27: 2025 | H27: 30

Sheet VERGE O
A1: Date : | B1: =TODAY() -> 46092
A3: N° Matricule : | C3: 190
A5: Nom Prénom : | C5: =VLOOKUP(C3,'Liste salariés'!A3:G104,2,FALSE) -> VERGE Olivier
A6: Date naissance : | C6: =VLOOKUP(C3,'Liste salariés'!A3:J103,6,FALSE) -> 25066 | D6: Age : | E6: =(B1-C6)/365 -> 57.605479
A7: Date d'entrée : | C7: =VLOOKUP(C3,'Liste salariés'!A3:J105,3,FALSE) -> 38169 | D7: Ancienneté : | E7: =(B1-C7)/365 -> 21.706849
A10: Liste des formations effectuées :
A12: Code formation | B12: Intitulé | E12: Organisme | F12: Date début | G12: Date fin | H12: Durée (h)
A13: 2002 | B13: IFOCA Initiation Personnel de Laboratoire | G13: 2011 | H13: 42
A14: 1003 | B14: Conduite Chariots Cat.5 | G14: 2012 | H14: 7
A15: 1010 | B15: Incendie | G15: 2012 | H15: 2.5
A16: 1026 | B16: Exposition Produits chimiques | G16: 2012 | H16: 3.5
A17: 3012 | B17: Poste 900 | G17: 2012 | H17: 151.67
A18: 1025 | B18: Manipulation Nanocharges | G18: 2013 | H18: 0.5
A19: 1026 | B19: Exposition Produits chimiques | G19: 2013 | H19: 1
A20: 3012 | B20: Poste 900 | G20: 2014 | H20: 151.67
A21: 1010 | B21: Incendie | G21: 2015 | H21: 3
A22: 2005 | B22: Formation LEAN | G22: 2015 | H22: 2
A23: 3012 | B23: Poste 900 | G23: 2016 | H23: 151.67
A24: 1009 | B24: Défibrillateur | G24: 2018 | H24: 3
... A32: 1030 | B32: Utilisation PTI | G32: 2023 | H32: 0.5

Sheet MOUSTROUS
A1: Date : | B1: =TODAY() -> 46092
A3: N° Matricule : | C3: 378
A5: Nom Prénom : | C5: =VLOOKUP(C3,'Liste salariés'!A3:G104,2,FALSE) -> MOUSTROUS Hervé
A6: Date naissance : | C6: =VLOOKUP(C3,'Liste salariés'!A3:J103,6,FALSE) -> 26215 | D6: Age : | E6: =(B1-C6)/365 -> 54.457534
A7: Date d'entrée : | C7: =VLOOKUP(C3,'Liste salariés'!A3:J105,3,FALSE) -> 43529 | D7: Ancienneté : | E7: =(B1-C7)/365 -> 7.0219178
A10: Liste des formations effectuées :
A12: Code formation | B12: Intitulé | E12: Organisme | F12: Date début | G12: Date fin | H12: Durée (h)
A13: 1009 | B13: Défibrillateur | G13: 2019 | H13: 2
A14: 1010 | B14: Incendie | G14: 2019 | H14: 2
A15: 1022 | B15: Sensibilisation au bruit | G15: 2019 | H15: 0.16
A16: 3040 | B16: Poste 1404 | G16: 2019 | H16: 151.67
A17: 3006 | B17: Poste 515 | G17: 2020 | H17: 151.67
A18: 1009 | B18: Défibrillateur | G18: 2023 | H18: 2
A19: 1010 | B19: Incendie | G19: 2023 | H19: 2
A20: 1009 | B20: Défibrillateur | G20: 2024 | H20: 2
A21: 1010 | B21: Incendie | G21: 2024 | H21: 2

Sheet VASSEUR
A1: Date : | B1: =TODAY() -> 46092
A3: N° Matricule : | C3: 326
A5: Nom Prénom : | C5: =VLOOKUP(C3,'Liste salariés'!A3:G104,2,FALSE) -> VASSEUR Joffrey
A6: Date naissance : | C6: =VLOOKUP(C3,'Liste salariés'!A3:J103,6,FALSE) -> 34163 | D6: Age : | E6: =(B1-C6)/365 -> 32.682192
A7: Date d'entrée : | C7: =VLOOKUP(C3,'Liste salariés'!A3:J105,3,FALSE) -> 41505 | D7: Ancienneté : | E7: =(B1-C7)/365 -> 12.567123
A10: Liste des formations effectuées :
A12: Code formation | B12: Intitulé | E12: Organisme | F12: Date début | G12: Date fin | H12: Durée (h)
A13: 3002 | B13: Poste 507 | G13: 2013 | H13: 151.67
A14: 1004 | B14: Conduite Chariots Cat.3 | G14: 2014 | H14: 7
A15: 3002 | B15: Poste 507 | G15: 2014 | H15: 151.67
A16: 3005 | B16: Poste 514 | G16: 2014 | H16: 151.67
A17: 3006 | B17: Poste 515 | G17: 2014 | H17: 151.67
A18: 3040 | B18: Poste 1404 | G18: 2015 | H18: 151.67
A19: 3002 | B19: Poste 507 | G19: 2016 | H19: 151.67
A20: 3005 | B20: Poste 514 | G20: 2016 | H20: 151.67
A21: 3006 | B21: Poste 515 | G21: 2016 | H21: 151.67
A22: 2007 | B22: ERP DIVALTO | G22: 2017 | H22: 7
A23: 3040 | B23: Poste 1404 | G23: 2017 | H23: 140
A24: 3002 | B24: Poste 507 | G24: 2018 | H24: 151.67
... A53: 3004 | B53: Poste 510 | G53: 2025 | H53: 105

Sheet COUCHINAVE E
A1: Date : | B1: =TODAY() -> 46092
A3: N° Matricule : | C3: 318
A5: Nom Prénom : | C5: =VLOOKUP(C3,'Liste salariés'!A3:G104,2,FALSE) -> COUCHINAVE Eric
A6: Date naissance : | C6: =VLOOKUP(C3,'Liste salariés'!A3:J103,6,FALSE) -> 28343 | D6: Age : | E6: =(B1-C6)/365 -> 48.627397
A7: Date d'entrée : | C7: =VLOOKUP(C3,'Liste salariés'!A3:J105,3,FALSE) -> 41337 | D7: Ancienneté : | E7: =(B1-C7)/365 -> 13.027397
A10: Liste des formations effectuées :
A12: Code formation | B12: Intitulé | E12: Organisme | F12: Date début | G12: Date fin | H12: Durée (h)
A13: 3002 | B13: Poste 507 | G13: 2013 | H13: 151.67
A14: 1004 | B14: Conduite Chariots Cat.3 | G14: 2014 | H14: 7
A15: 3002 | B15: Poste 507 | G15: 2015 | H15: 151.67
A16: 3002 | B16: Poste 507 | G16: 2017 | H16: 151.67
A17: 3003 | B17: Poste 509 | G17: 2017 | H17: 151.67
A18: 3006 | B18: Poste 515 | G18: 2017 | H18: 151.67
A19: 2007 | B19: ERP DIVALTO | G19: 2017 | H19: 2
A20: 1020 | B20: Prévention TMS - Gestes Postures et Nutrition | G20: 2018 | H20: 3.5
A21: 1021 | B21: Gestion du stress | G21: 2018 | H21: 4
A22: 1004 | B22: Conduite Chariots Cat.3 | G22: 2019 | H22: 7
A23: 1008 | B23: Habilitation électrique HC/H2V/HE Manœuvre | G23: 2019 | H23: 3
A24: 1009 | B24: Défibrillateur | G24: 2019 | H24: 3
... A40: 3048 | B40: Poste 561 | G40: 2025 | H40: 30

Sheet CAMPANE
A1: Date : | B1: =TODAY() -> 46092
A3: N° Matricule : | C3: 462
A5: Nom Prénom : | C5: =VLOOKUP(C3,'Liste salariés'!A3:G104,2,FALSE) -> CAMPANE Jean François
A6: Date naissance : | C6: =VLOOKUP(C3,'Liste salariés'!A3:J103,6,FALSE) -> 24251 | D6: Age : | E6: =(B1-C6)/365 -> 59.838356
A7: Date d'entrée : | C7: =VLOOKUP(C3,'Liste salariés'!A3:J105,3,FALSE) -> 44837 | D7: Ancienneté : | E7: =(B1-C7)/365 -> 3.4383562
A10: Liste des formations effectuées :
A12: Code formation | B12: Intitulé | E12: Organisme | F12: Date début | G12: Date fin | H12: Durée (h)
A13: 3005 | B13: Poste 514 | G13: 2022 | H13: 151.67
A14: 3006 | B14: Poste 515 | G14: 2022 | H14: 151.67
A15: 1004 | B15: Conduite Chariots Cat.3 | G15: 2023 | H15: 10.5
A16: 1020 | B16: Prévention TMS - Gestes Postures et Nutrition | G16: 2024 | H16: 3.5
A17: 3007 | B17: Poste 516 | G17: 2024 | H17: 151.67
A18: 3007 | B18: Poste 516 | G18: 2025 | H18: 105

Sheet RICE
A1: Date : | B1: =TODAY() -> 46092
A3: N° Matricule : | C3: 435
A5: Nom Prénom : | C5: =VLOOKUP(C3,'Liste salariés'!A3:G104,2,FALSE) -> RICE Matthew
A6: Date naissance : | C6: =VLOOKUP(C3,'Liste salariés'!A3:J103,6,FALSE) -> 26201 | D6: Age : | E6: =(B1-C6)/365 -> 54.49589
A7: Date d'entrée : | C7: =VLOOKUP(C3,'Liste salariés'!A3:J105,3,FALSE) -> 44424 | D7: Ancienneté : | E7: =(B1-C7)/365 -> 4.569863
A10: Liste des formations effectuées :
A12: Code formation | B12: Intitulé | E12: Organisme | F12: Date début | G12: Date fin | H12: Durée (h)
A13: 3015 | B13: Poste 903 | G13: 2021 | H13: 151.67
A14: 3037 | B14: Poste 1121 | G14: 2021 | H14: 151.67
A15: 3022 | B15: Poste 920 | G15: 2023 | H15: 151.67
A16: 1009 | B16: Défibrillateur | G16: 2024 | H16: 2
A17: 1010 | B17: Incendie | G17: 2024 | H17: 2
A18: 3037 | B18: Poste 1121 | G18: 2024 | H18: 151.67

Sheet GONOT
A1: Date : | B1: =TODAY() -> 46092
A3: N° Matricule : | C3: 414
A5: Nom Prénom : | C5: =VLOOKUP(C3,'Liste salariés'!A3:G104,2,FALSE) -> GONOT Damien
A6: Date naissance : | C6: =VLOOKUP(C3,'Liste salariés'!A3:J103,6,FALSE) -> 36319 | D6: Age : | E6: =(B1-C6)/365 -> 26.775342
A7: Date d'entrée : | C7: =VLOOKUP(C3,'Liste salariés'!A3:J105,3,FALSE) -> 44158 | D7: Ancienneté : | E7: =(B1-C7)/365 -> 5.2986301
A10: Liste des formations effectuées :
A12: Code formation | B12: Intitulé | E12: Organisme | F12: Date début | G12: Date fin | H12: Durée (h)
A13: 3038 | B13: Poste 1401 | G13: 2020 | H13: 120
A14: 1004 | B14: Conduite Chariots Cat.3 | G14: 2021 | H14: 7
A15: 3013 | B15: Poste 901 | G15: 2021 | H15: 396.67
A16: 3018 | B16: Poste 906 | G16: 2021 | H16: 151.67
A17: 3023 | B17: Poste 923 | G17: 2021 | H17: 151.67
A18: 3038 | B18: Poste 1401 | G18: 2021 | H18: 151.67
A19: 3001 | B19: Poste 506 | G19: 2022 | H19: 151.67
A20: 3024 | B20: Poste 924 | G20: 2022 | H20: 151.67
A21: 1002 | B21: Conduite Chariots Cat.3 et Cat.5 | G21: 2023 | H21: 14
A22: 1012 | B22: ATEX Niveau 0 - Sensibilisation | G22: 2023 | H22: 3.5
A23: 1014 | B23: Membres CSE | G23: 2023 | H23: 35
A24: 3039 | B24: Poste 1402 | G24: 2023 | H24: 151.67
... A31: 1006 | B31: Habilitation électrique BE Manœuvre BS | G31: 2024 | H31: 14

Sheet JOUMAH 
A1: Date : | B1: =TODAY() -> 46092
A3: N° Matricule : | C3: 258
A5: Nom Prénom : | C5: =VLOOKUP(C3,'Liste salariés'!A3:G104,2,FALSE) -> JOUMAH HASSAN
A6: Date naissance : | C6: =VLOOKUP(C3,'Liste salariés'!A3:J103,6,FALSE) -> 22426 | D6: Age : | E6: =(B1-C6)/365 -> 64.838356
A7: Date d'entrée : | C7: =VLOOKUP(C3,'Liste salariés'!A3:J105,3,FALSE) -> 39364 | D7: Ancienneté : | E7: =(B1-C7)/365 -> 18.432877
A10: Liste des formations effectuées :
A12: Code formation | B12: Intitulé | E12: Organisme | F12: Date début | G12: Date fin | H12: Durée (h)
A13: 2046 | B13: =VLOOKUP(A13,'Liste Formations'!$A$5:$B$154,2,FALSE) -> IFOCA - Formulation des caoutchoucs : INITIATION | G13: 2009 | H13: 35
A14: 2003 | B14: =VLOOKUP(A14,'Liste Formations'!$A$5:$B$154,2,FALSE) -> CIRAD / Les secrets d'un polymère | G14: 2011 | H14: 14
A15: 2005 | B15: =VLOOKUP(A15,'Liste Formations'!$A$5:$B$154,2,FALSE) -> Formation LEAN | G15: 2011 | H15: 7
A16: 2014 | B16: =VLOOKUP(A16,'Liste Formations'!$A$5:$B$154,2,FALSE) -> Gestion Projet + ISO T.S. | G16: 2013 | H16: 7
A17: 1011 | B17: =VLOOKUP(A17,'Liste Formations'!$A$5:$B$154,2,FALSE) -> UTI.COM - SSI / CHUBB | G17: 2014 | H17: 4
A18: 2007 | B18: =VLOOKUP(A18,'Liste Formations'!$A$5:$B$154,2,FALSE) -> ERP DIVALTO | G18: 2016 | H18: 7
A19: 2029 | B19: =VLOOKUP(A19,'Liste Formations'!$A$5:$B$154,2,FALSE) -> CORE TOOLS | G19: 2016 | H19: 7
A20: 2007 | B20: =VLOOKUP(A20,'Liste Formations'!$A$5:$B$154,2,FALSE) -> ERP DIVALTO | G20: 2017 | H20: 21
A21: 1021 | B21: =VLOOKUP(A21,'Liste Formations'!$A$5:$B$154,2,FALSE) -> Gestion du stress | G21: 2018 | H21: 4
A22: 2007 | B22: =VLOOKUP(A22,'Liste Formations'!$A$5:$B$154,2,FALSE) -> ERP DIVALTO | G22: 2019 | H22: 14
A23: 2021 | B23: =VLOOKUP(A23,'Liste Formations'!$A$5:$B$154,2,FALSE) -> ENTERPRISE / ALPHA TECHNOLOGIE | G23: 2019 | H23: 7
A24: 1009 | B24: =VLOOKUP(A24,'Liste Formations'!$A$5:$B$154,2,FALSE) -> Défibrillateur | G24: 2019 | H24: 3
... A27: 2040 | B27: =VLOOKUP(A27,'Liste Formations'!$A$5:$B$154,2,FALSE) -> Anglais | G27: 2024 | H27: 13.5

Sheet BIDONDO P
A1: Date : | B1: =TODAY() -> 46092
A3: N° Matricule : | C3: 46
A5: Nom Prénom : | C5: =VLOOKUP(C3,'Liste salariés'!A3:G104,2,FALSE) -> BIDONDO Pierre
A6: Date naissance : | C6: =VLOOKUP(C3,'Liste salariés'!A3:J103,6,FALSE) -> 24408 | D6: Age : | E6: =(B1-C6)/365 -> 59.408219
A7: Date d'entrée : | C7: =VLOOKUP(C3,'Liste salariés'!A3:J105,3,FALSE) -> 33340 | D7: Ancienneté : | E7: =(B1-C7)/365 -> 34.936986
A10: Liste des formations effectuées :
A12: Code formation | B12: Intitulé | E12: Organisme | F12: Date début | G12: Date fin | H12: Durée (h)
A13: 3039 | B13: Poste 1402 | G13: 2010 | H13: 151.67
A14: 3038 | B14: Poste 1401 | G14: 2011 | H14: 151.67
A15: 3039 | B15: Poste 1402 | G15: 2011 | H15: 151.67
A16: 3040 | B16: Poste 1404 | G16: 2011 | H16: 151.67
A17: 3041 | B17: Poste 1405 | G17: 2011 | H17: 151.67
A18: 3043 | B18: Poste 1412 | G18: 2011 | H18: 151.67
A19: 2001 | B19: IFOCA le mélangeage | G19: 2011 | H19: 42
A20: 1003 | B20: Conduite Chariots Cat.5 | G20: 2012 | H20: 7
A21: 1006 | B21: Habilitation électrique BE Manœuvre BS | G21: 2012 | H21: 14
A22: 3038 | B22: Poste 1401 | G22: 2013 | H22: 151.67
A23: 3039 | B23: Poste 1402 | G23: 2013 | H23: 151.67
A24: 3040 | B24: Poste 1404 | G24: 2013 | H24: 151.67
... A63: 2051 | B63: Manager et animer une équipe | G63: 2025 | H63: 28

Sheet SARALEGUI 
A1: Date : | B1: =TODAY() -> 46092
A3: N° Matricule : | C3: 59
A5: Nom Prénom : | C5: =VLOOKUP(C3,'Liste salariés'!A3:G104,2,FALSE) -> SARALEGUI Eric
A6: Date naissance : | C6: =VLOOKUP(C3,'Liste salariés'!A3:J103,6,FALSE) -> 24510 | D6: Age : | E6: =(B1-C6)/365 -> 59.128767
A7: Date d'entrée : | C7: =VLOOKUP(C3,'Liste salariés'!A3:J105,3,FALSE) -> 33298 | D7: Ancienneté : | E7: =(B1-C7)/365 -> 35.052055
A10: Liste des formations effectuées :
A12: Code formation | B12: Intitulé | E12: Organisme | F12: Date début | G12: Date fin | H12: Durée (h)
A13: 3002 | B13: Poste 507 | G13: 2011 | H13: 151.67
A14: 3039 | B14: Poste 1402 | G14: 2011 | H14: 151.67
A15: 1010 | B15: Incendie | G15: 2012 | H15: 2.5
A16: 3039 | B16: Poste 1402 | G16: 2013 | H16: 151.67
A17: 3039 | B17: Poste 1402 | G17: 2017 | H17: 151.67
A18: 3002 | B18: Poste 507 | G18: 2017 | H18: 151.67
A19: 2007 | B19: ERP DIVALTO | G19: 2017 | H19: 7
A20: 3006 | B20: Poste 515 | G20: 2018 | H20: 151.67
A21: 1022 | B21: Sensibilisation au bruit | G21: 2019 | H21: 0.16
A22: 3002 | B22: Poste 507 | G22: 2019 | H22: 151.67
A23: 3006 | B23: Poste 515 | G23: 2019 | H23: 151.67
A24: 3039 | B24: Poste 1402 | G24: 2019 | H24: 151.67
... A30: 1010 | B30: Incendie | G30: 2024 | H30: 2

Sheet BRANKAER
A1: Date : | B1: =TODAY() -> 46092
A3: N° Matricule : | C3: 347
A5: Nom Prénom : | C5: =VLOOKUP(C3,'Liste salariés'!A3:G104,2,FALSE) -> BRANKAER Alexandre
A6: Date naissance : | C6: =VLOOKUP(C3,'Liste salariés'!A3:J103,6,FALSE) -> 33637 | D6: Age : | E6: =(B1-C6)/365 -> 34.123288
A7: Date d'entrée : | C7: =VLOOKUP(C3,'Liste salariés'!A3:J105,3,FALSE) -> 42177 | D7: Ancienneté : | E7: =(B1-C7)/365 -> 10.726027
A10: Liste des formations effectuées :
A12: Code formation | B12: Intitulé | E12: Organisme | F12: Date début | G12: Date fin | H12: Durée (h)
A13: 2031 | B13: Qualité | G13: 2015 | H13: 0.25
A14: 3012 | B14: Poste 900 | G14: 2015 | H14: 151.67
A15: 3043 | B15: Poste 1412 | G15: 2015 | H15: 151.67
A16: 1004 | B16: Conduite Chariots Cat.3 | G16: 2015 | H16: 7
A17: 3012 | B17: Poste 900 | G17: 2017 | H17: 151.67
A18: 3043 | B18: Poste 1412 | G18: 2017 | H18: 151.67
A19: 2007 | B19: ERP DIVALTO | G19: 2017 | H19: 2
A20: 3012 | B20: Poste 900 | G20: 2019 | H20: 151.67
A21: 3043 | B21: Poste 1412 | G21: 2019 | H21: 151.67
A22: 1003 | B22: Conduite Chariots Cat.5 | G22: 2020 | H22: 7
A23: 1004 | B23: Conduite Chariots Cat.3 | G23: 2021 | H23: 7
A24: 1004 | B24: Conduite Chariots Cat.3 | G24: 2023 | H24: 7
... A29: 1020 | B29: Prévention TMS - Gestes Postures et Nutrition | G29: 2024 | H29: 3.5

Sheet BEHEREGARAY
A1: Date : | B1: =TODAY() -> 46092
A3: N° Matricule : | C3: 56
A5: Nom Prénom : | C5: =VLOOKUP(C3,'Liste salariés'!A3:G104,2,FALSE) -> BEHEREGARAY Jean Michel
A6: Date naissance : | C6: =VLOOKUP(C3,'Liste salariés'!A3:J103,6,FALSE) -> 23778 | D6: Age : | E6: =(B1-C6)/365 -> 61.134247
A7: Date d'entrée : | C7: =VLOOKUP(C3,'Liste salariés'!A3:J105,3,FALSE) -> 33303 | D7: Ancienneté : | E7: =(B1-C7)/365 -> 35.038356
A10: Liste des formations effectuées :
A12: Code formation | B12: Intitulé | E12: Organisme | F12: Date début | G12: Date fin | H12: Durée (h)
A13: 3025 | B13: Poste 930 | G13: 2010 | H13: 151.67
A14: 3007 | B14: Poste 516 | G14: 2011 | H14: 151.67
A15: 3012 | B15: Poste 900 | G15: 2011 | H15: 151.67
A16: 3020 | B16: Poste 908 | G16: 2011 | H16: 151.67
A17: 3021 | B17: Poste 912 | G17: 2011 | H17: 151.67
A18: 3025 | B18: Poste 930 | G18: 2011 | H18: 151.67
A19: 3043 | B19: Poste 1412 | G19: 2011 | H19: 151.67
A20: 1010 | B20: Incendie | G20: 2012 | H20: 2.5
A21: 1024 | B21: Déversement granulés | G21: 2012 | H21: 1
A22: 3012 | B22: Poste 900 | G22: 2013 | H22: 151.67
A23: 3020 | B23: Poste 908 | G23: 2013 | H23: 151.67
A24: 3021 | B24: Poste 912 | G24: 2013 | H24: 151.67
... A37: 2007 | B37: ERP DIVALTO | G37: 2016 | H37: 7
A38: 1412 | B38: #N/A | G38: 2016 | H38: 151.67
A39: 3020 | B39: Poste 908 | G39: 2017 | H39: 151.67
A40: 3012 | B40: Poste 900 | G40: 2017 | H40: 151.67
A41: 2007 | B41: ERP DIVALTO | G41: 2017 | H41: 3
A42: 1017 | B42: Recyclage S.S.T. Recyclage Sauveteurs Secourites du Travail | G42: 2017 | H42: 7
A43: 1008 | B43: Habilitation électrique HC/H2V/HE Manœuvre | G43: 2017 | H43: 2
A44: 1009 | B44: Défibrillateur | G44: 2017 | H44: 2
A45: 1004 | B45: Conduite Chariots Cat.3 | G45: 2018 | H45: 7
A46: 1020 | B46: Prévention TMS - Gestes Postures et Nutrition | G46: 2018 | H46: 3.5
A47: 3043 | B47: Poste 1412 | G47: 2018 | H47: 151.67
A48: 3012 | B48: Poste 900 | G48: 2019 | H48: 151.67
A49: 1017 | B49: Recyclage S.S.T. Recyclage Sauveteurs Secourites du Travail | G49: 2019 | H49: 7
A50: 2007 | B50: ERP DIVALTO | G50: 2020 | H50: 2.5
... A64: 2051 | B64: Manager et animer une équipe | G64: 2025 | H64: 28

Sheet SICRE
A1: Date : | B1: =TODAY() -> 46092
A3: N° Matricule : | C3: 48
A5: Nom Prénom : | C5: =VLOOKUP(C3,'Liste salariés'!A3:G104,2,FALSE) -> SICRE Pierre
A6: Date naissance : | C6: =VLOOKUP(C3,'Liste salariés'!A3:J103,6,FALSE) -> 25875 | D6: Age : | E6: =(B1-C6)/365 -> 55.389041
A7: Date d'entrée : | C7: =VLOOKUP(C3,'Liste salariés'!A3:J105,3,FALSE) -> 33338 | D7: Ancienneté : | E7: =(B1-C7)/365 -> 34.942466
A10: Liste des formations effectuées :
A12: Code formation | B12: Intitulé | E12: Organisme | F12: Date début | G12: Date fin | H12: Durée (h)
A13: 3001 | B13: Poste 506 | G13: 2010 | H13: 151.67
A14: 3002 | B14: Poste 507 | G14: 2010 | H14: 151.67
A15: 3004 | B15: Poste 510 | G15: 2010 | H15: 151.67
A16: 1004 | B16: Conduite Chariots Cat.3 | G16: 2010 | H16: 7
A17: 3003 | B17: Poste 509 | G17: 2011 | H17: 151.67
A18: 3001 | B18: Poste 506 | G18: 2012 | H18: 151.67
A19: 1006 | B19: Habilitation électrique BE Manœuvre BS | G19: 2012 | H19: 7
A20: 3003 | B20: Poste 509 | G20: 2013 | H20: 151.67
A21: 3005 | B21: Poste 514 | G21: 2013 | H21: 151.67
A22: 3006 | B22: Poste 515 | G22: 2013 | H22: 151.67
A23: 3001 | B23: Poste 506 | G23: 2015 | H23: 151.67
A24: 3002 | B24: Poste 507 | G24: 2015 | H24: 151.67
... A72: 3048 | B72: Poste 561 | G72: 2025 | H72: 35

Sheet DELGADO
A1: Date : | B1: =TODAY() -> 46092
A3: N° Matricule : | C3: 379
A5: Nom Prénom : | C5: =VLOOKUP(C3,'Liste salariés'!A3:G104,2,FALSE) -> DELGADO Cédric
A6: Date naissance : | C6: =VLOOKUP(C3,'Liste salariés'!A3:J103,6,FALSE) -> 29936 | D6: Age : | E6: =(B1-C6)/365 -> 44.263014
A7: Date d'entrée : | C7: =VLOOKUP(C3,'Liste salariés'!A3:J105,3,FALSE) -> 43536 | D7: Ancienneté : | E7: =(B1-C7)/365 -> 7.0027397
A10: Liste des formations effectuées :
A12: Code formation | B12: Intitulé | E12: Organisme | F12: Date début | G12: Date fin | H12: Durée (h)
A13: 1004 | B13: Conduite Chariots Cat.3 | G13: 2019 | H13: 7
A14: 3005 | B14: Poste 514 | G14: 2019 | H14: 151.67
A15: 3006 | B15: Poste 515 | G15: 2019 | H15: 151.67
A16: 3002 | B16: Poste 507 | G16: 2020 | H16: 151.67
A17: 3007 | B17: Poste 516 | G17: 2020 | H17: 151.67
A18: 3016 | B18: Poste 904 | G18: 2020 | H18: 26
A19: 3028 | B19: Poste 942 | G19: 2020 | H19: 66
A20: 3032 | B20: Poste 1100 | G20: 2020 | H20: 151.67
A21: 3005 | B21: Poste 514 | G21: 2021 | H21: 151.67
A22: 3015 | B22: Poste 903 | G22: 2021 | H22: 151.67
A23: 3016 | B23: Poste 904 | G23: 2021 | H23: 151.67
A24: 1007 | B24: Habilitation électrique BR/BC/B2V/HOV | G24: 2024 | H24: 7
... A29: 3048 | B29: Poste 561 | G29: 2025 | H29: 30

Sheet CORDANI
A1: Date : | B1: =TODAY() -> 46092
A3: N° Matricule : | C3: 341
A5: Nom Prénom : | C5: =VLOOKUP(C3,'Liste salariés'!A3:G104,2,FALSE) -> CORDANI Jean Marie
A6: Date naissance : | C6: =VLOOKUP(C3,'Liste salariés'!A3:J103,6,FALSE) -> 27912 | D6: Age : | E6: =(B1-C6)/365 -> 49.808219
A7: Date d'entrée : | C7: =VLOOKUP(C3,'Liste salariés'!A3:J105,3,FALSE) -> 42101 | D7: Ancienneté : | E7: =(B1-C7)/365 -> 10.934247
A10: Liste des formations effectuées :
A12: Code formation | B12: Intitulé | E12: Organisme | F12: Date début | G12: Date fin | H12: Durée (h)
A13: 2031 | B13: Qualité | G13: 2015 | H13: 0.25
A14: 3001 | B14: Poste 506 | G14: 2015 | H14: 151.67
A15: 3001 | B15: Poste 506 | G15: 2017 | H15: 151.67
A16: 2007 | B16: ERP DIVALTO | G16: 2017 | H16: 2
A17: 1020 | B17: Prévention TMS - Gestes Postures et Nutrition | G17: 2018 | H17: 3.5
A18: 1002 | B18: Conduite Chariots Cat.3 et Cat.5 | G18: 2019 | H18: 14
A19: 1016 | B19: S.S.T. Sauveteurs Secourites du Travail | G19: 2019 | H19: 14
A20: 3001 | B20: Poste 506 | G20: 2019 | H20: 151.67
A21: 3002 | B21: Poste 507 | G21: 2019 | H21: 151.67
A22: 3023 | B22: Poste 923 | G22: 2019 | H22: 151.67
A23: 3013 | B23: Poste 901 | G23: 2020 | H23: 120
A24: 3001 | B24: Poste 506 | G24: 2021 | H24: 151.67
... A29: 1017 | B29: Recyclage S.S.T. Recyclage Sauveteurs Secourites du Travail | G29: 2025 | H29: 7

Sheet ETCHEVERRY F
A1: Date : | B1: =TODAY() -> 46092
A3: N° Matricule : | C3: 336
A5: Nom Prénom : | C5: =VLOOKUP(C3,'Liste salariés'!A3:G104,2,FALSE) -> ETCHEVERRY Frédéric
A6: Date naissance : | C6: =VLOOKUP(C3,'Liste salariés'!A3:J103,6,FALSE) -> 30215 | D6: Age : | E6: =(B1-C6)/365 -> 43.49863
A7: Date d'entrée : | C7: =VLOOKUP(C3,'Liste salariés'!A3:J105,3,FALSE) -> 42016 | D7: Ancienneté : | E7: =(B1-C7)/365 -> 11.167123
A10: Liste des formations effectuées :
A12: Code formation | B12: Intitulé | E12: Organisme | F12: Date début | G12: Date fin | H12: Durée (h)
A13: 1004 | B13: Conduite Chariots Cat.3 | G13: 2015 | H13: 7
A14: 1009 | B14: Défibrillateur | G14: 2015 | H14: 3
A15: 2005 | B15: Formation LEAN | G15: 2015 | H15: 2
A16: 3020 | B16: Poste 908 | G16: 2015 | H16: 151.67
A17: 3020 | B17: Poste 908 | G17: 2017 | H17: 151.67
A18: 2007 | B18: ERP DIVALTO | G18: 2017 | H18: 3
A19: 1008 | B19: Habilitation électrique HC/H2V/HE Manœuvre | G19: 2018 | H19: 3
A20: 1009 | B20: Défibrillateur | G20: 2018 | H20: 3
A21: 1020 | B21: Prévention TMS - Gestes Postures et Nutrition | G21: 2018 | H21: 3.5
A22: 3012 | B22: Poste 900 | G22: 2018 | H22: 151.67
A23: 3043 | B23: Poste 1412 | G23: 2018 | H23: 151.67
A24: 1028 | B24: PRAP IBC | G24: 2019 | H24: 14
... A35: 3037 | B35: Poste 1121 | G35: 2024 | H35: 151.67

Sheet AGUERRE
A1: Date : | B1: =TODAY() -> 46092
A3: N° Matricule : | C3: 330
A5: Nom Prénom : | C5: =VLOOKUP(C3,'Liste salariés'!A3:G104,2,FALSE) -> AGUERRE Stéphane
A6: Date naissance : | C6: =VLOOKUP(C3,'Liste salariés'!A3:J103,6,FALSE) -> 25788 | D6: Age : | E6: =(B1-C6)/365 -> 55.627397
A7: Date d'entrée : | C7: =VLOOKUP(C3,'Liste salariés'!A3:J105,3,FALSE) -> 41666 | D7: Ancienneté : | E7: =(B1-C7)/365 -> 12.126027
A10: Liste des formations effectuées :
A12: Code formation | B12: Intitulé | E12: Organisme | F12: Date début | G12: Date fin | H12: Durée (h)
A13: 1004 | B13: Conduite Chariots Cat.3 | G13: 2014 | H13: 7
A14: 3025 | B14: Poste 930 | G14: 2014 | H14: 151.67
A15: 3041 | B15: Poste 1405 | G15: 2014 | H15: 151.67
A16: 3025 | B16: Poste 930 | G16: 2016 | H16: 151.67
A17: 3041 | B17: Poste 1405 | G17: 2016 | H17: 151.67
A18: 2007 | B18: ERP DIVALTO | G18: 2017 | H18: 2
A19: 1020 | B19: Prévention TMS - Gestes Postures et Nutrition | G19: 2018 | H19: 3.5
A20: 3010 | B20: Poste 830 | G20: 2018 | H20: 151.67
A21: 3025 | B21: Poste 930 | G21: 2018 | H21: 151.67
A22: 3041 | B22: Poste 1405 | G22: 2018 | H22: 151.67
A23: 1004 | B23: Conduite Chariots Cat.3 | G23: 2019 | H23: 7
A24: 3014 | B24: Poste 902 | G24: 2021 | H24: 151.67
... A30: 3037 | B30: Poste 1121 | G30: 2025 | H30: 35
